<?xml version="1.0" encoding="UTF-8"?>
<testsuite name="test_room_reservation_tests.TestHotelReservation-20240419202233" tests="6" file="test_room_reservation_tests.py" time="0.066" timestamp="2024-04-19T20:22:33" failures="6" errors="0" skipped="0">
	<testcase classname="test_room_reservation_tests.TestHotelReservation" name="test_duplicated_id_reservation_tests" time="0.002" timestamp="2024-04-19T20:22:33">
		<failure type="AssertionError" message="HotelManagementException not raised"><![CDATA[Traceback (most recent call last):
  File "/Library/Frameworks/Python.framework/Versions/3.10/lib/python3.10/unittest/case.py", line 59, in testPartExecutor
    yield
  File "/Library/Frameworks/Python.framework/Versions/3.10/lib/python3.10/unittest/case.py", line 591, in run
    self._callTestMethod(testMethod)
  File "/Library/Frameworks/Python.framework/Versions/3.10/lib/python3.10/unittest/case.py", line 549, in _callTestMethod
    method()
  File "/Users/ellaz-j/PycharmProjects/G88.2024.T06.EG3/src/unittest/python/test_room_reservation_tests.py", line 121, in test_duplicated_id_reservation_tests
    with self.assertRaises(HotelManagementException) as c_m:
  File "/Library/Frameworks/Python.framework/Versions/3.10/lib/python3.10/unittest/case.py", line 226, in __exit__
    self._raiseFailure("{} not raised".format(exc_name))
  File "/Library/Frameworks/Python.framework/Versions/3.10/lib/python3.10/unittest/case.py", line 163, in _raiseFailure
    raise self.test_case.failureException(msg)
AssertionError: HotelManagementException not raised
]]></failure>
	</testcase>
	<testcase classname="test_room_reservation_tests.TestHotelReservation" name="test_duplicated_reservation_tests" time="0.003" timestamp="2024-04-19T20:22:33">
		<failure type="AssertionError" message="HotelManagementException not raised"><![CDATA[Traceback (most recent call last):
  File "/Library/Frameworks/Python.framework/Versions/3.10/lib/python3.10/unittest/case.py", line 59, in testPartExecutor
    yield
  File "/Library/Frameworks/Python.framework/Versions/3.10/lib/python3.10/unittest/case.py", line 591, in run
    self._callTestMethod(testMethod)
  File "/Library/Frameworks/Python.framework/Versions/3.10/lib/python3.10/unittest/case.py", line 549, in _callTestMethod
    method()
  File "/Users/ellaz-j/PycharmProjects/G88.2024.T06.EG3/venv/lib/python3.10/site-packages/freezegun/api.py", line 827, in wrapper
    result = func(*args, **kwargs)
  File "/Users/ellaz-j/PycharmProjects/G88.2024.T06.EG3/src/unittest/python/test_room_reservation_tests.py", line 68, in test_duplicated_reservation_tests
    with self.assertRaises(HotelManagementException) as c_m:
  File "/Library/Frameworks/Python.framework/Versions/3.10/lib/python3.10/unittest/case.py", line 226, in __exit__
    self._raiseFailure("{} not raised".format(exc_name))
  File "/Library/Frameworks/Python.framework/Versions/3.10/lib/python3.10/unittest/case.py", line 163, in _raiseFailure
    raise self.test_case.failureException(msg)
AssertionError: HotelManagementException not raised
]]></failure>
	</testcase>
	<testcase classname="test_room_reservation_tests.TestHotelReservation" name="test_parametrized_cases_tests [TC1VALID]" time="0.000" timestamp="0001-01-01T00:00:00">
		<failure type="AssertionError" message="False is not true"><![CDATA[Traceback (most recent call last):
  File "/Library/Frameworks/Python.framework/Versions/3.10/lib/python3.10/unittest/case.py", line 59, in testPartExecutor
    yield
  File "/Library/Frameworks/Python.framework/Versions/3.10/lib/python3.10/unittest/case.py", line 498, in subTest
    yield
  File "/Users/ellaz-j/PycharmProjects/G88.2024.T06.EG3/src/unittest/python/test_room_reservation_tests.py", line 187, in test_parametrized_cases_tests
    self.assertTrue(found)
  File "/Library/Frameworks/Python.framework/Versions/3.10/lib/python3.10/unittest/case.py", line 687, in assertTrue
    raise self.failureException(msg)
AssertionError: False is not true
]]></failure>
	</testcase>
	<testcase classname="test_room_reservation_tests.TestHotelReservation" name="test_parametrized_cases_tests [TC2VALID]" time="0.000" timestamp="0001-01-01T00:00:00">
		<failure type="AssertionError" message="False is not true"><![CDATA[Traceback (most recent call last):
  File "/Library/Frameworks/Python.framework/Versions/3.10/lib/python3.10/unittest/case.py", line 59, in testPartExecutor
    yield
  File "/Library/Frameworks/Python.framework/Versions/3.10/lib/python3.10/unittest/case.py", line 498, in subTest
    yield
  File "/Users/ellaz-j/PycharmProjects/G88.2024.T06.EG3/src/unittest/python/test_room_reservation_tests.py", line 187, in test_parametrized_cases_tests
    self.assertTrue(found)
  File "/Library/Frameworks/Python.framework/Versions/3.10/lib/python3.10/unittest/case.py", line 687, in assertTrue
    raise self.failureException(msg)
AssertionError: False is not true
]]></failure>
	</testcase>
	<testcase classname="test_room_reservation_tests.TestHotelReservation" name="test_parametrized_cases_tests [TC3VALID]" time="0.000" timestamp="0001-01-01T00:00:00">
		<failure type="AssertionError" message="False is not true"><![CDATA[Traceback (most recent call last):
  File "/Library/Frameworks/Python.framework/Versions/3.10/lib/python3.10/unittest/case.py", line 59, in testPartExecutor
    yield
  File "/Library/Frameworks/Python.framework/Versions/3.10/lib/python3.10/unittest/case.py", line 498, in subTest
    yield
  File "/Users/ellaz-j/PycharmProjects/G88.2024.T06.EG3/src/unittest/python/test_room_reservation_tests.py", line 187, in test_parametrized_cases_tests
    self.assertTrue(found)
  File "/Library/Frameworks/Python.framework/Versions/3.10/lib/python3.10/unittest/case.py", line 687, in assertTrue
    raise self.failureException(msg)
AssertionError: False is not true
]]></failure>
	</testcase>
	<testcase classname="test_room_reservation_tests.TestHotelReservation" name="test_parametrized_cases_tests [TC4VALID]" time="0.061" timestamp="2024-04-19T20:22:33">
		<failure type="AssertionError" message="False is not true"><![CDATA[Traceback (most recent call last):
  File "/Library/Frameworks/Python.framework/Versions/3.10/lib/python3.10/unittest/case.py", line 59, in testPartExecutor
    yield
  File "/Library/Frameworks/Python.framework/Versions/3.10/lib/python3.10/unittest/case.py", line 498, in subTest
    yield
  File "/Users/ellaz-j/PycharmProjects/G88.2024.T06.EG3/src/unittest/python/test_room_reservation_tests.py", line 187, in test_parametrized_cases_tests
    self.assertTrue(found)
  File "/Library/Frameworks/Python.framework/Versions/3.10/lib/python3.10/unittest/case.py", line 687, in assertTrue
    raise self.failureException(msg)
AssertionError: False is not true
]]></failure>
	</testcase>
</testsuite>
