<?xml version="1.0" encoding="UTF-8"?>
<testsuite name="test_guest_arrival_tests.TestHotelReservation-20240421185454" tests="3" file="test_guest_arrival_tests.py" time="0.008" timestamp="2024-04-21T18:54:54" failures="0" errors="3" skipped="0">
	<testcase classname="test_guest_arrival_tests.TestHotelReservation" name="test_case_valid_reservation_invalid_arrival_date" time="0.003" timestamp="2024-04-21T18:54:54">
		<error type="NameError" message="name 'data_list' is not defined"><![CDATA[Traceback (most recent call last):
  File "/Library/Developer/CommandLineTools/Library/Frameworks/Python3.framework/Versions/3.9/lib/python3.9/unittest/case.py", line 59, in testPartExecutor
    yield
  File "/Library/Developer/CommandLineTools/Library/Frameworks/Python3.framework/Versions/3.9/lib/python3.9/unittest/case.py", line 589, in run
    self._callSetUp()
  File "/Library/Developer/CommandLineTools/Library/Frameworks/Python3.framework/Versions/3.9/lib/python3.9/unittest/case.py", line 547, in _callSetUp
    self.setUp()
  File "/Users/a19787/PycharmProjects/G88.2024.T06.EG3/src/unittest/python/test_guest_arrival_tests.py", line 37, in setUp
    localizer = hotel_mngr.room_reservation(credit_card="5105105105105100",
  File "/Users/a19787/PycharmProjects/G88.2024.T06.EG3/src/main/python/uc3m_travel/hotel_manager.py", line 93, in room_reservation
    data_list.append(my_reservation.__dict__)
NameError: name 'data_list' is not defined
]]></error>
	</testcase>
	<testcase classname="test_guest_arrival_tests.TestHotelReservation" name="test_get_reservation_data_manipulated_tests" time="0.002" timestamp="2024-04-21T18:54:54">
		<error type="NameError" message="name 'data_list' is not defined"><![CDATA[Traceback (most recent call last):
  File "/Library/Developer/CommandLineTools/Library/Frameworks/Python3.framework/Versions/3.9/lib/python3.9/unittest/case.py", line 59, in testPartExecutor
    yield
  File "/Library/Developer/CommandLineTools/Library/Frameworks/Python3.framework/Versions/3.9/lib/python3.9/unittest/case.py", line 589, in run
    self._callSetUp()
  File "/Library/Developer/CommandLineTools/Library/Frameworks/Python3.framework/Versions/3.9/lib/python3.9/unittest/case.py", line 547, in _callSetUp
    self.setUp()
  File "/Users/a19787/PycharmProjects/G88.2024.T06.EG3/src/unittest/python/test_guest_arrival_tests.py", line 37, in setUp
    localizer = hotel_mngr.room_reservation(credit_card="5105105105105100",
  File "/Users/a19787/PycharmProjects/G88.2024.T06.EG3/src/main/python/uc3m_travel/hotel_manager.py", line 93, in room_reservation
    data_list.append(my_reservation.__dict__)
NameError: name 'data_list' is not defined
]]></error>
	</testcase>
	<testcase classname="test_guest_arrival_tests.TestHotelReservation" name="test_parametrized_cases_tests" time="0.002" timestamp="2024-04-21T18:54:54">
		<error type="NameError" message="name 'data_list' is not defined"><![CDATA[Traceback (most recent call last):
  File "/Library/Developer/CommandLineTools/Library/Frameworks/Python3.framework/Versions/3.9/lib/python3.9/unittest/case.py", line 59, in testPartExecutor
    yield
  File "/Library/Developer/CommandLineTools/Library/Frameworks/Python3.framework/Versions/3.9/lib/python3.9/unittest/case.py", line 589, in run
    self._callSetUp()
  File "/Library/Developer/CommandLineTools/Library/Frameworks/Python3.framework/Versions/3.9/lib/python3.9/unittest/case.py", line 547, in _callSetUp
    self.setUp()
  File "/Users/a19787/PycharmProjects/G88.2024.T06.EG3/src/unittest/python/test_guest_arrival_tests.py", line 37, in setUp
    localizer = hotel_mngr.room_reservation(credit_card="5105105105105100",
  File "/Users/a19787/PycharmProjects/G88.2024.T06.EG3/src/main/python/uc3m_travel/hotel_manager.py", line 93, in room_reservation
    data_list.append(my_reservation.__dict__)
NameError: name 'data_list' is not defined
]]></error>
	</testcase>
</testsuite>
