<?xml version="1.0" encoding="UTF-8"?>
<testsuite name="test_room_reservation_tests.TestHotelReservation-20240426191544" tests="3" file="test_room_reservation_tests.py" time="0.100" timestamp="2024-04-26T19:15:44" failures="1" errors="0" skipped="0">
	<testcase classname="test_room_reservation_tests.TestHotelReservation" name="test_duplicated_id_reservation_tests" time="0.001" timestamp="2024-04-26T19:15:44"/>
	<testcase classname="test_room_reservation_tests.TestHotelReservation" name="test_parametrized_cases_tests" time="0.094" timestamp="2024-04-26T19:15:44"/>
	<testcase classname="test_room_reservation_tests.TestHotelReservation" name="test_duplicated_reservation_tests" time="0.005" timestamp="2024-04-26T19:15:44">
		<failure type="AssertionError" message="'This ID card has another reservation' != 'Reservation already exists'
- This ID card has another reservation
+ Reservation already exists
"><![CDATA[Traceback (most recent call last):
  File "/Library/Frameworks/Python.framework/Versions/3.10/lib/python3.10/unittest/case.py", line 59, in testPartExecutor
    yield
  File "/Library/Frameworks/Python.framework/Versions/3.10/lib/python3.10/unittest/case.py", line 591, in run
    self._callTestMethod(testMethod)
  File "/Library/Frameworks/Python.framework/Versions/3.10/lib/python3.10/unittest/case.py", line 549, in _callTestMethod
    method()
  File "/Users/ellaz-j/PycharmProjects/G88.2024.T06.EG3/venv/lib/python3.10/site-packages/freezegun/api.py", line 827, in wrapper
    result = func(*args, **kwargs)
  File "/Users/ellaz-j/PycharmProjects/G88.2024.T06.EG3/src/unittest/python/test_room_reservation_tests.py", line 76, in test_duplicated_reservation_tests
    self.assertEqual(c_m.exception.message, "Reservation already exists")
  File "/Library/Frameworks/Python.framework/Versions/3.10/lib/python3.10/unittest/case.py", line 845, in assertEqual
    assertion_func(first, second, msg=msg)
  File "/Library/Frameworks/Python.framework/Versions/3.10/lib/python3.10/unittest/case.py", line 1226, in assertMultiLineEqual
    self.fail(self._formatMessage(msg, standardMsg))
  File "/Library/Frameworks/Python.framework/Versions/3.10/lib/python3.10/unittest/case.py", line 675, in fail
    raise self.failureException(msg)
AssertionError: 'This ID card has another reservation' != 'Reservation already exists'
- This ID card has another reservation
+ Reservation already exists

]]></failure>
	</testcase>
</testsuite>
