<?xml version="1.0" encoding="UTF-8"?>
<testsuite name="test_room_reservation_tests.TestHotelReservation-20240419161549" tests="3" file="test_room_reservation_tests.py" time="0.068" timestamp="2024-04-19T16:15:50" failures="2" errors="0" skipped="0">
	<testcase classname="test_room_reservation_tests.TestHotelReservation" name="test_parametrized_cases_tests" time="0.061" timestamp="2024-04-19T16:15:50"/>
	<testcase classname="test_room_reservation_tests.TestHotelReservation" name="test_duplicated_id_reservation_tests" time="0.003" timestamp="2024-04-19T16:15:50">
		<failure type="AssertionError" message="HotelManagementException not raised"><![CDATA[Traceback (most recent call last):
  File "/Library/Developer/CommandLineTools/Library/Frameworks/Python3.framework/Versions/3.9/lib/python3.9/unittest/case.py", line 59, in testPartExecutor
    yield
  File "/Library/Developer/CommandLineTools/Library/Frameworks/Python3.framework/Versions/3.9/lib/python3.9/unittest/case.py", line 593, in run
    self._callTestMethod(testMethod)
  File "/Library/Developer/CommandLineTools/Library/Frameworks/Python3.framework/Versions/3.9/lib/python3.9/unittest/case.py", line 550, in _callTestMethod
    method()
  File "/Users/a19787/PycharmProjects/G88.2024.T06.EG3/src/unittest/python/test_room_reservation_tests.py", line 122, in test_duplicated_id_reservation_tests
    mngr.room_reservation(credit_card=credit_card_number,
  File "/Library/Developer/CommandLineTools/Library/Frameworks/Python3.framework/Versions/3.9/lib/python3.9/unittest/case.py", line 226, in __exit__
    self._raiseFailure("{} not raised".format(exc_name))
  File "/Library/Developer/CommandLineTools/Library/Frameworks/Python3.framework/Versions/3.9/lib/python3.9/unittest/case.py", line 163, in _raiseFailure
    raise self.test_case.failureException(msg)
AssertionError: HotelManagementException not raised
]]></failure>
	</testcase>
	<testcase classname="test_room_reservation_tests.TestHotelReservation" name="test_duplicated_reservation_tests" time="0.004" timestamp="2024-04-19T16:15:50">
		<failure type="AssertionError" message="HotelManagementException not raised"><![CDATA[Traceback (most recent call last):
  File "/Library/Developer/CommandLineTools/Library/Frameworks/Python3.framework/Versions/3.9/lib/python3.9/unittest/case.py", line 59, in testPartExecutor
    yield
  File "/Library/Developer/CommandLineTools/Library/Frameworks/Python3.framework/Versions/3.9/lib/python3.9/unittest/case.py", line 593, in run
    self._callTestMethod(testMethod)
  File "/Library/Developer/CommandLineTools/Library/Frameworks/Python3.framework/Versions/3.9/lib/python3.9/unittest/case.py", line 550, in _callTestMethod
    method()
  File "/Users/a19787/PycharmProjects/G88.2024.T06.EG3/.venv/lib/python3.9/site-packages/freezegun/api.py", line 827, in wrapper
    result = func(*args, **kwargs)
  File "/Users/a19787/PycharmProjects/G88.2024.T06.EG3/src/unittest/python/test_room_reservation_tests.py", line 69, in test_duplicated_reservation_tests
    mngr.room_reservation(credit_card=credit_card_number,
  File "/Library/Developer/CommandLineTools/Library/Frameworks/Python3.framework/Versions/3.9/lib/python3.9/unittest/case.py", line 226, in __exit__
    self._raiseFailure("{} not raised".format(exc_name))
  File "/Library/Developer/CommandLineTools/Library/Frameworks/Python3.framework/Versions/3.9/lib/python3.9/unittest/case.py", line 163, in _raiseFailure
    raise self.test_case.failureException(msg)
AssertionError: HotelManagementException not raised
]]></failure>
	</testcase>
</testsuite>
